Workbook

Sheet Hoja9
C2: Cantidad | D2: Valor Venta | E2: Descuentos | F2: Costo
A3: No usar este | B3: Todas | C3: 4367 | D3: 69669850 | E3: -2957750 | F3: 27156689 | G3: Toda la empresa
A4: usar | B4: Default | C4: 3114 | D4: 43714200 | E4: -307100 | F4: 16756600 | G4: Moongcook
A5: usar | B5: Rappi | C5: 593 | D5: 8289850 | E5: -2256550 | F5: 2119104 | G5: Rappi
A6: usar | B6: Delivery | C6: 660 | D6: 17665800 | E6: -394100 | F6: 8280985 | G6: Delivery
C7: =SUM(C4:C6) -> 4367 | D7: =SUM(D4:D6) -> 69669850 | E7: =SUM(E4:E6) -> -2957750 | F7: =SUM(F4:F6) -> 27156689
C9: ESTE CASO ES ENERO DE 2026

Sheet RAIZ
I2: PLATOS PERSONALES / COMBOS
I3: CANTIDAD | J3: PRECIO | K3: COSTO | L3: % CANT | M3: % PRECIO
I4: 2117 | J4: 4000000 | K4: 3000000 | L4: =I4/(#REF!+#REF!+#REF!+#REF!) -> #REF! | M4: =J4/(#REF!+#REF!+#REF!+#REF!) -> #REF!
I5: PLATOS PERSONALES / PLATOS ESPECIALES
I6: CANTIDAD | J6: PRECIO | K6: COSTO | L6: % CANT | M6: % PRECIO
I7: 4000 | J7: 15500000 | K7: 5000000 | L7: =I7/(#REF!+#REF!+#REF!+#REF!) -> #REF! | M7: =J7/(#REF!+#REF!+#REF!+#REF!) -> #REF!
I8: PLATOS PERSONALES BOWLS
A9: Cantidad es = a numero de platos | D9: precio = valor del plato | G9: costo = valor de producirlo | I9: CANTIDAD | J9: PRECIO | K9: COSTO | L9: % CANT | M9: % PRECIO
I10: 4000 | J10: 12500000 | K10: 5000000 | L10: =I10/(#REF!+#REF!+#REF!+#REF!) -> #REF! | M10: =J10/(#REF!+#REF!+#REF!+#REF!) -> #REF!
I11: PLATOS PERSONALES CAJAS
I12: CANTIDAD | J12: PRECIO | K12: COSTO | L12: % CANT | M12: % PRECIO
I13: 4000 | J13: 12500000 | K13: 5000000 | L13: =I13/(#REF!+#REF!+#REF!+#REF!) -> #REF! | M13: =J13/(#REF!+#REF!+#REF!+#REF!) -> #REF!
A14: TOTAL | D14: PLATOS PERSONALES
A15: CANTIDAD | B15: PRECIO | C15: COSTO | D15: CANTIDAD | E15: PRECIO | F15: COSTO | G15: % CANT | H15: % PRECIO
A16: 16117 | B16: 54000000 | C16: 20000000 | D16: 14117 | E16: 44000000 | F16: 18000000 | G16: =D16/(D16+D19) -> 0.87590743 | H16: =E16/(E16+E19) -> 0.81481481 | N16: ESTE PRIMER DASHBOARD ES EL VERSUS ENTRE PERSONALES Y NO PERSONALES /PARA COMPARTIR
D17: PLATOS PARA COMPARTIR
D18: CANTIDAD | E18: PRECIO | F18: COSTO
D19: 2000 | E19: 10000000 | F19: 2000000 | G19: =D19/(D19+D16) -> 0.12409257 | H19: =E19/(E19+E16) -> 0.18518519
I20: PLATOS NO PERSONALES/ COMBOS
I21: CANTIDAD | J21: PRECIO | K21: COSTO | L21: % CANT | M21: % PRECIO
I22: 300 | J22: 2000000 | K22: 18000000 | L22: =I22/(#REF!+#REF!+#REF!+#REF!) -> #REF! | M22: =J22/(#REF!+#REF!+#REF!+#REF!) -> #REF!
I23: PLATOS NO PERSONALES/ PLATOS ESPECIALES
I24: CANTIDAD | J24: PRECIO | K24: COSTO | L24: % CANT | M24: % PRECIO
I25: 200 | J25: 1000000 | K25: 18000000 | L25: =I25/(#REF!+#REF!+#REF!+#REF!) -> #REF! | M25: =J25/(#REF!+#REF!+#REF!+#REF!) -> #REF!
I26: PLATOS NO PERSONALESBOWLS
I27: CANTIDAD | J27: PRECIO | K27: COSTO | L27: % CANT | M27: % PRECIO
I28: 750 | J28: 3500000 | K28: 18000000 | L28: =I28/(#REF!+#REF!+#REF!+#REF!) -> #REF! | M28: =J28/(#REF!+#REF!+#REF!+#REF!) -> #REF!
I29: PLATOS NO PERSONALESCAJAS
I30: CANTIDAD | J30: PRECIO | K30: COSTO | L30: % CANT | M30: % PRECIO
I31: 750 | J31: 3500000 | K31: 18000000 | L31: =I31/(#REF!+#REF!+#REF!+#REF!) -> #REF! | M31: =J31/(#REF!+#REF!+#REF!+#REF!) -> #REF!
J39: PUNTO DE VENTA | P39: DELIVERY | V39: RAPPI
I40: PLATOS PERSONALES / COMBOS | O40: PLATOS PERSONALES / COMBOS | U40: PLATOS PERSONALES / COMBOS
I41: CANTIDAD | J41: PRECIO | K41: COSTO | L41: % CANT | M41: % PRECIO | O41: CANTIDAD | P41: PRECIO | Q41: COSTO | R41: % CANT | S41: % PRECIO | U41: CANTIDAD | V41: PRECIO | W41: COSTO | X41: % CANT | Y41: % PRECIO
L42: =I42/(#REF!+#REF!+#REF!+#REF!) -> #REF! | M42: =J42/(#REF!+#REF!+#REF!+#REF!) -> #REF! | R42: =O42/(#REF!+#REF!+#REF!+#REF!) -> #REF! | S42: =P42/(#REF!+#REF!+#REF!+#REF!) -> #REF! | X42: =U42/(#REF!+#REF!+#REF!+#REF!) -> #REF! | Y42: =V42/(#REF!+#REF!+#REF!+#REF!) -> #REF!
I43: PLATOS PERSONALES / PLATOS ESPECIALES | O43: PLATOS PERSONALES / PLATOS ESPECIALES | U43: PLATOS PERSONALES / PLATOS ESPECIALES
I44: CANTIDAD | J44: PRECIO | K44: COSTO | L44: % CANT | M44: % PRECIO | O44: CANTIDAD | P44: PRECIO | Q44: COSTO | R44: % CANT | S44: % PRECIO | U44: CANTIDAD | V44: PRECIO | W44: COSTO | X44: % CANT | Y44: % PRECIO
L45: =I45/(#REF!+#REF!+#REF!+#REF!) -> #REF! | M45: =J45/(#REF!+#REF!+#REF!+#REF!) -> #REF! | R45: =O45/(#REF!+#REF!+#REF!+#REF!) -> #REF! | S45: =P45/(#REF!+#REF!+#REF!+#REF!) -> #REF! | X45: =U45/(#REF!+#REF!+#REF!+#REF!) -> #REF! | Y45: =V45/(#REF!+#REF!+#REF!+#REF!) -> #REF!
I46: PLATOS PERSONALES BOWLS | O46: PLATOS PERSONALES BOWLS | U46: PLATOS PERSONALES BOWLS
I47: CANTIDAD | J47: PRECIO | K47: COSTO | L47: % CANT | M47: % PRECIO | O47: CANTIDAD | P47: PRECIO | Q47: COSTO | R47: % CANT | S47: % PRECIO | U47: CANTIDAD | V47: PRECIO | W47: COSTO | X47: % CANT | Y47: % PRECIO
L48: =I48/(#REF!+#REF!+#REF!+#REF!) -> #REF! | M48: =J48/(#REF!+#REF!+#REF!+#REF!) -> #REF! | R48: =O48/(#REF!+#REF!+#REF!+#REF!) -> #REF! | S48: =P48/(#REF!+#REF!+#REF!+#REF!) -> #REF! | X48: =U48/(#REF!+#REF!+#REF!+#REF!) -> #REF! | Y48: =V48/(#REF!+#REF!+#REF!+#REF!) -> #REF!
...

Sheet DIFERENCIAS
A3: Suma de VENTA | C3: UNIDAD DE NEGOCIO
A4: AÑO | B4: MES | C4: DELIVERY | D4: RAPPI | E4: PUNTO DE VENTA | F4: Total general | H4: Mauricio | I4: hoy | J4: diferencia
A5: 2025 | B5: ENERO | D5: 2754700 | E5: 37078300 | F5: 39833000 | H5: 39853000 | I5: 39833000 | J5: =I5-H5 -> -20000
B6: NOVIEMBRE | C6: 17114900 | D6: 6839150 | E6: 37896900 | F6: 61850950 | H6: 40262150 | I6: 61850950 | J6: =I6-H6 -> 21588800
B7: DICIEMBRE | C7: 18791288 | D7: 8591250 | E7: 40581410 | F7: 67963948 | H7: 44808350 | I7: 67963948 | J7: =I7-H7 -> 23155598
B8: OCTUBRE | C8: 12334600 | D8: 7261550 | E8: 32613800 | F8: 52209950 | H8: 38728650 | I8: 52209950 | J8: =I8-H8 -> 13481300
B9: SEPTIEMBRE | C9: 16006100 | D9: 3102999 | E9: 31623400 | F9: 50732499 | H9: 39549750 | I9: 50732499 | J9: =I9-H9 -> 11182749
B10: AGOSTO | C10: 13499400 | D10: 4520399 | E10: 32793700 | F10: 50813499 | H10: 50134800 | I10: 50813499 | J10: =I10-H10 -> 678699
B11: JULIO | C11: 11214500 | D11: 3663100 | E11: 29399700 | F11: 44277300 | H11: 44279300 | I11: 44277300 | J11: =I11-H11 -> -2000
B12: JUNIO | C12: 13945800 | D12: 4583300 | E12: 32712900 | F12: 51242000 | H12: 54004699 | I12: 51242000 | J12: =I12-H12 -> -2762699
B13: MAYO | C13: 2394500 | D13: 5181000 | E13: 31974150 | F13: 39549650 | H13: 50732449 | I13: 39549650 | J13: =I13-H13 -> -11182799
B14: ABRIL | D14: 6504250 | E14: 32224100 | F14: 38728350 | H14: 52209950 | I14: 38728350 | J14: =I14-H14 -> -13481600
B15: MARZO | D15: 7104050 | E15: 37701600 | F15: 44805650 | H15: 59835490 | I15: 44805650 | J15: =I15-H15 -> -15029840
B16: FEBRERO | D16: 4570850 | E16: 35691300 | F16: 40262150 | H16: 67607160 | I16: 40262150 | J16: =I16-H16 -> -27345010
A17: Total 2025 | C17: 105301088 | D17: 64676598 | E17: 412291260 | F17: 582268946 | H17: =SUM(H5:H16) -> 582005748 | I17: =SUM(I5:I16) -> 582268946 | J17: =I17-H17 -> 263198
A18: 2026 | B18: ENERO | C18: 17665800 | D18: 8289850 | E18: 43714200 | F18: 69669850
A19: Total 2026 | C19: 17665800 | D19: 8289850 | E19: 43714200 | F19: 69669850
A20: Total general | C20: 122966888 | D20: 72966448 | E20: 456005460 | F20: 651938796

Sheet VENTAS X UND. NEG.
A1: AÑO | B1: MES | C1: UNIDAD DE NEGOCIO | D1: ID | E1: PRODUCTO | F1: CANTIDAD | G1: VENTA | H1: DESCUENTO | I1: COSTO | J1: UTILIDAD BRUTA | K1: MARGEN BRUTO | L1: % DCTO. | M1: JERARQUIA | N1: TIPO | O1: EMPAQUE
A2: 2026 | B2: ENERO | C2: DELIVERY | D2: MON101 | E2: Chow fan especial trio | F2: 47 | G2: 1875300 | H2: 0 | I2: 942491 | J2: =G2-I2 -> 932809 | K2: =IFERROR(J2/G2,0) -> 0.49741855 | L2: =IFERROR((H2/G2)*-1,0) -> 0 | M2: =VLOOKUP(D2,'Jer-Tip-Emp'!B:E,4,0) -> Platos mong | N2: =VLOOKUP(D2,'Jer-Tip-Emp'!B:F,5,0) -> No Personal | O2: =VLOOKUP(D2,'Jer-Tip-Emp'!B:G,6,0) -> Platos Especiales
A3: 2026 | B3: ENERO | C3: DELIVERY | D3: COMP01 | E3: COMBO 1- Valenciano personal | F3: 39 | G3: 932100 | H3: 0 | I3: 375453 | J3: =G3-I3 -> 556647 | K3: =IFERROR(J3/G3,0) -> 0.59719665 | L3: =IFERROR((H3/G3)*-1,0) -> 0 | M3: =VLOOKUP(D3,'Jer-Tip-Emp'!B:E,4,0) -> Combos personales | N3: =VLOOKUP(D3,'Jer-Tip-Emp'!B:F,5,0) -> Personal | O3: =VLOOKUP(D3,'Jer-Tip-Emp'!B:G,6,0) -> Combo
A4: 2026 | B4: ENERO | C4: DELIVERY | D4: ENT04 | E4: LUMPIAS X 2 | F4: 38 | G4: 331915 | H4: -6285 | I4: 119282 | J4: =G4-I4 -> 212633 | K4: =IFERROR(J4/G4,0) -> 0.64062486 | L4: =IFERROR((H4/G4)*-1,0) -> 0.018935571 | M4: =VLOOKUP(D4,'Jer-Tip-Emp'!B:E,4,0) -> Entradas | N4: =VLOOKUP(D4,'Jer-Tip-Emp'!B:F,5,0) -> Otro | O4: =VLOOKUP(D4,'Jer-Tip-Emp'!B:G,6,0) -> Otro
A5: 2026 | B5: ENERO | C5: DELIVERY | D5: MON132 | E5: Chow Fan Valenciano familiar | F5: 38 | G5: 2293853 | H5: -248347 | I5: 1316890 | J5: =G5-I5 -> 976963 | K5: =IFERROR(J5/G5,0) -> 0.4259048 | L5: =IFERROR((H5/G5)*-1,0) -> 0.10826631 | M5: =VLOOKUP(D5,'Jer-Tip-Emp'!B:E,4,0) -> Platos mong | N5: =VLOOKUP(D5,'Jer-Tip-Emp'!B:F,5,0) -> No Personal | O5: =VLOOKUP(D5,'Jer-Tip-Emp'!B:G,6,0) -> Caja
A6: 2026 | B6: ENERO | C6: DELIVERY | D6: MON102 | E6: Chow Fan Especial familiar | F6: 28 | G6: 1390524 | H6: -6676 | I6: 905828 | J6: =G6-I6 -> 484696 | K6: =IFERROR(J6/G6,0) -> 0.34857075 | L6: =IFERROR((H6/G6)*-1,0) -> 0.0048010678 | M6: =VLOOKUP(D6,'Jer-Tip-Emp'!B:E,4,0) -> Platos mong | N6: =VLOOKUP(D6,'Jer-Tip-Emp'!B:F,5,0) -> No Personal | O6: =VLOOKUP(D6,'Jer-Tip-Emp'!B:G,6,0) -> Caja
A7: 2026 | B7: ENERO | C7: DELIVERY | D7: COMP02 | E7: COMBO 2 - Chow fan especial personal | F7: 28 | G7: 725200 | H7: 0 | I7: 266028 | J7: =G7-I7 -> 459172 | K7: =IFERROR(J7/G7,0) -> 0.63316602 | L7: =IFERROR((H7/G7)*-1,0) -> 0 | M7: =VLOOKUP(D7,'Jer-Tip-Emp'!B:E,4,0) -> Combos personales | N7: =VLOOKUP(D7,'Jer-Tip-Emp'!B:F,5,0) -> Personal | O7: =VLOOKUP(D7,'Jer-Tip-Emp'!B:G,6,0) -> Combo
A8: 2026 | B8: ENERO | C8: DELIVERY | D8: MON450 | E8: Arma tu plato | F8: 22 | G8: 545116 | H8: -2684 | I8: 0 | J8: =G8-I8 -> 545116 | K8: =IFERROR(J8/G8,0) -> 1 | L8: =IFERROR((H8/G8)*-1,0) -> 0.0049237227 | M8: =VLOOKUP(D8,'Jer-Tip-Emp'!B:E,4,0) -> Arma tu plato | N8: =VLOOKUP(D8,'Jer-Tip-Emp'!B:F,5,0) -> Personal | O8: =VLOOKUP(D8,'Jer-Tip-Emp'!B:G,6,0) -> Caja
A9: 2026 | B9: ENERO | C9: DELIVERY | D9: ADIC564 | E9: Adición Presa de pollo | F9: 20 | G9: 137505 | H9: -495 | I9: 49280 | J9: =G9-I9 -> 88225 | K9: =IFERROR(J9/G9,0) -> 0.64161303 | L9: =IFERROR((H9/G9)*-1,0) -> 0.0035998691 | M9: =VLOOKUP(D9,'Jer-Tip-Emp'!B:E,4,0) -> Adición | N9: =VLOOKUP(D9,'Jer-Tip-Emp'!B:F,5,0) -> Adición | O9: =VLOOKUP(D9,'Jer-Tip-Emp'!B:G,6,0) -> Adición
A10: 2026 | B10: ENERO | C10: DELIVERY | D10: COMP03 | E10: COMBO 3 - Chop suey especial personal | F10: 19 | G10: 549100 | H10: 0 | I10: 181830 | J10: =G10-I10 -> 367270 | K10: =IFERROR(J10/G10,0) -> 0.66885813 | L10: =IFERROR((H10/G10)*-1,0) -> 0 | M10: =VLOOKUP(D10,'Jer-Tip-Emp'!B:E,4,0) -> Combos personales | N10: =VLOOKUP(D10,'Jer-Tip-Emp'!B:F,5,0) -> Personal | O10: =VLOOKUP(D10,'Jer-Tip-Emp'!B:G,6,0) -> Combo
A11: 2026 | B11: ENERO | C11: DELIVERY | D11: MON131 | E11: Chow Fan Valenciano trio | F11: 17 | G11: 848300 | H11: 0 | I11: 319906 | J11: =G11-I11 -> 528394 | K11: =IFERROR(J11/G11,0) -> 0.62288577 | L11: =IFERROR((H11/G11)*-1,0) -> 0 | M11: =VLOOKUP(D11,'Jer-Tip-Emp'!B:E,4,0) -> Platos mong | N11: =VLOOKUP(D11,'Jer-Tip-Emp'!B:F,5,0) -> No Personal | O11: =VLOOKUP(D11,'Jer-Tip-Emp'!B:G,6,0) -> Caja
A12: 2026 | B12: ENERO | C12: DELIVERY | D12: COMC02 | E12: COMBO AMIGOS | F12: 17 | G12: 915613 | H12: -687 | I12: 401846 | J12: =G12-I12 -> 513767 | K12: =IFERROR(J12/G12,0) -> 0.56111807 | L12: =IFERROR((H12/G12)*-1,0) -> 0.000750317 | M12: =VLOOKUP(D12,'Jer-Tip-Emp'!B:E,4,0) -> Combos para compartir | N12: =VLOOKUP(D12,'Jer-Tip-Emp'!B:F,5,0) -> No Personal | O12: =VLOOKUP(D12,'Jer-Tip-Emp'!B:G,6,0) -> Combo
A13: 2026 | B13: ENERO | C13: DELIVERY | D13: BEB598 | E13: Coca Cola 1,5 litros | F13: 17 | G13: 163818 | H13: -4482 | I13: 76517 | J13: =G13-I13 -> 87301 | K13: =IFERROR(J13/G13,0) -> 0.53291458 | L13: =IFERROR((H13/G13)*-1,0) -> 0.027359631 | M13: =VLOOKUP(D13,'Jer-Tip-Emp'!B:E,4,0) -> Bebidas | N13: =VLOOKUP(D13,'Jer-Tip-Emp'!B:F,5,0) -> Bebidas | O13: =VLOOKUP(D13,'Jer-Tip-Emp'!B:G,6,0) -> Bebidas
... A2775: 2025 | B2775: ENERO | C2775: RAPPI | D2775: PESP05 | E2775: WONG- Menú infantil | F2775: 1 | G2775: 19900 | H2775: 0 | I2775: 7125 | J2775: =G2775-I2775 -> 12775 | K2775: =IFERROR(J2775/G2775,0) -> 0.6419598 | L2775: =IFERROR((H2775/G2775)*-1,0) -> 0 | M2775: =VLOOKUP(D2775,'Jer-Tip-Emp'!B:E,4,0) -> Platos especiales | N2775: =VLOOKUP(D2775,'Jer-Tip-Emp'!B:F,5,0) -> Personal | O2775: =VLOOKUP(D2775,'Jer-Tip-Emp'!B:G,6,0) -> Platos especiales

Sheet Jer-Tip-Emp
A1: Tipo | B1: ID Producto ** | C1: Nombre Producto * | D1: Costo | E1: Jerarquia | F1: Tipo | G1: Familia
A2: Extras | B2: ADIC01 | C2: Papas a la Francesa ADIC | D2: 2049 | E2: Adición | F2: Adición | G2: Adición
A3: Extras | B3: ADIC02 | C3: Pollo presa ADIC | D3: 2849 | E3: Adición | F3: Adición | G3: Adición
A4: Extras | B4: ADIC03 | C4: Camarones | D4: 3108 | E4: Adición | F4: Adición | G4: Adición
A5: Extras | B5: ADIC04 | C5: Pollo picado | D5: 1747 | E5: Adición | F5: Adición | G5: Adición
A6: Extras | B6: ADIC05 | C6: Vegetales salteados | D6: 7 | E6: Adición | F6: Adición | G6: Adición
A7: Extras | B7: ADIC06 | C7: Arroz Frito ADIC | D7: 1282 | E7: Adición | F7: Adición | G7: Adición
A8: Extras | B8: ADIC07 | C8: Lumpia X 1 | D8: 1569 | E8: Adición | F8: Adición | G8: Adición
A9: Extras | B9: ADIC08 | C9: Salsa agridulce Roja | D9: 59 | E9: Adición | F9: Adición | G9: Adición
A10: Extras | B10: ADIC09 | C10: No deseo | D10: 0 | E10: Adición | F10: Adición | G10: Adición
A11: Extras | B11: ADIC10 | C11: Cubiertos + servilletas | D11: 321 | E11: Adición | F11: Adición | G11: Adición
A12: Extras | B12: ADIC11 | C12: Salsa Teriyaki | D12: 0 | E12: Adición | F12: Adición | G12: Adición
A13: Extras | B13: ADIC12 | C13: Salsa Soya | D13: 0 | E13: Adición | F13: Adición | G13: Adición
... A244: Producto | B244: TOTEATDVYERROR | C244: Producto ERROR Integraciones | D244: 0 | E244: Otro | F244: Otro | G244: Otro
